laplace_adapt.py line 146, in dpg_laplace_adapt
    solver.solve()
RuntimeError: 

*** -------------------------------------------------------------------------
*** DOLFIN encountered an error. If you are not able to resolve this issue
*** using the information listed below, you can ask for help at
***
***     fenics-support@googlegroups.com
***
*** Remember to include the error message listed below and, if possible,
*** include a *minimal* running example to reproduce the error.
***
*** -------------------------------------------------------------------------
*** Error:   Unable to successfully call PETSc function 'KSPSolve'.
*** Reason:  PETSc error code is: 76 (Error in external library).
*** Where:   This error was encountered inside /home/conda/feedstock_root/build_artifacts/fenics-pkgs_1565954390126/work/dolfin/dolfin/la/PETScKrylovSolver.cpp.
*** Process: 0
*** 
*** DOLFIN version: 2019.1.0
*** Git changeset:  76bf12b24408e3ce2364eb22e62c802a92c90ff2
*** -------------------------------------------------------------------------
